Workbook

Sheet TOPIC
A1: GROUP PROJECT – ONLINE SHOPPING BEHAVIOR
A4: MAS291 | Statistical analysis of purchasing intention and transaction completion
A6: Research topic and dataset
A7: Item | B7: Description
A8: Vietnamese title | B8: Phân tích hành vi người mua sắm trực tuyến và khả năng hoàn tất giao dịch
A9: English title | B9: Statistical Analysis of Online Shopping Behavior and Purchase Conversion
A10: Population | B10: Online shopping sessions represented by the UCI dataset
A11: Sample 1 | B11: Purchase completed (Revenue = TRUE): 1,908 independent sessions
A12: Sample 2 | B12: No purchase (Revenue = FALSE): 10,422 independent sessions
A13: Variables | B13: 18 original variables: page counts, time durations, bounce/exit rates, page value, device/browser, visitor type, weekend and revenue
A14: Source | B14: UCI Machine Learning Repository, dataset ID 468; CC BY 4.0
A16: Research questions
A17: Task | B17: Question
A18: 1 | B18: How do session behavior, data quality and distributions differ by conversion outcome?
A19: 2 | B19: What can be inferred about average product-page duration and the overall conversion rate?
A20: 3 | B20: Do buyers and non-buyers differ in product-page duration and returning-visitor proportion?
A21: 4 | B21: How strongly does the number of product pages predict total product-page duration?
A22: 5 | B22: Which results are statistically and practically important for an e-commerce platform?
A25: Design note: UCI states that each session belongs to a different user within the one-year collection period. Revenue=TRUE and Revenue=FALSE therefore form two distinct samples. The analysis is observational; associations must not be interpreted as causal effects.

Sheet DATA
A1: Session_ID | B1: Administrative | C1: Administrative_Duration | D1: Informational | E1: Informational_Duration | F1: ProductRelated | G1: ProductRelated_Duration | H1: BounceRates | I1: ExitRates | J1: PageValues | K1: SpecialDay | L1: Month | M1: OperatingSystems | N1: Browser | O1: Region | P1: TrafficType | Q1: VisitorType | R1: Weekend | S1: Revenue | T1: Revenue_int | U1: Weekend_int | V1: Returning_int
A2: 1 | B2: 0 | C2: 0 | D2: 0 | E2: 0 | F2: 1 | G2: 0 | H2: 0.2 | I2: 0.2 | J2: 0 | K2: 0 | L2: Feb | M2: 1 | N2: 1 | O2: 1 | P2: 1 | Q2: Returning_Visitor | R2: =FALSE() -> FALSE | S2: =FALSE() -> FALSE | T2: 0 | U2: 0 | V2: 1
A3: 2 | B3: 0 | C3: 0 | D3: 0 | E3: 0 | F3: 2 | G3: 64 | H3: 0 | I3: 0.1 | J3: 0 | K3: 0 | L3: Feb | M3: 2 | N3: 2 | O3: 1 | P3: 2 | Q3: Returning_Visitor | R3: =FALSE() -> FALSE | S3: =FALSE() -> FALSE | T3: 0 | U3: 0 | V3: 1
A4: 3 | B4: 0 | C4: 0 | D4: 0 | E4: 0 | F4: 1 | G4: 0 | H4: 0.2 | I4: 0.2 | J4: 0 | K4: 0 | L4: Feb | M4: 4 | N4: 1 | O4: 9 | P4: 3 | Q4: Returning_Visitor | R4: =FALSE() -> FALSE | S4: =FALSE() -> FALSE | T4: 0 | U4: 0 | V4: 1
A5: 4 | B5: 0 | C5: 0 | D5: 0 | E5: 0 | F5: 2 | G5: 2.6666667 | H5: 0.05 | I5: 0.14 | J5: 0 | K5: 0 | L5: Feb | M5: 3 | N5: 2 | O5: 2 | P5: 4 | Q5: Returning_Visitor | R5: =FALSE() -> FALSE | S5: =FALSE() -> FALSE | T5: 0 | U5: 0 | V5: 1
A6: 5 | B6: 0 | C6: 0 | D6: 0 | E6: 0 | F6: 10 | G6: 627.5 | H6: 0.02 | I6: 0.05 | J6: 0 | K6: 0 | L6: Feb | M6: 3 | N6: 3 | O6: 1 | P6: 4 | Q6: Returning_Visitor | R6: =TRUE() -> TRUE | S6: =FALSE() -> FALSE | T6: 0 | U6: 1 | V6: 1
A7: 6 | B7: 0 | C7: 0 | D7: 0 | E7: 0 | F7: 19 | G7: 154.21667 | H7: 0.015789474 | I7: 0.024561404 | J7: 0 | K7: 0 | L7: Feb | M7: 2 | N7: 2 | O7: 1 | P7: 3 | Q7: Returning_Visitor | R7: =FALSE() -> FALSE | S7: =FALSE() -> FALSE | T7: 0 | U7: 0 | V7: 1
A8: 7 | B8: 0 | C8: 0 | D8: 0 | E8: 0 | F8: 1 | G8: 0 | H8: 0.2 | I8: 0.2 | J8: 0 | K8: 0.4 | L8: Feb | M8: 2 | N8: 4 | O8: 3 | P8: 3 | Q8: Returning_Visitor | R8: =FALSE() -> FALSE | S8: =FALSE() -> FALSE | T8: 0 | U8: 0 | V8: 1
A9: 8 | B9: 1 | C9: 0 | D9: 0 | E9: 0 | F9: 0 | G9: 0 | H9: 0.2 | I9: 0.2 | J9: 0 | K9: 0 | L9: Feb | M9: 1 | N9: 2 | O9: 1 | P9: 5 | Q9: Returning_Visitor | R9: =TRUE() -> TRUE | S9: =FALSE() -> FALSE | T9: 0 | U9: 1 | V9: 1
A10: 9 | B10: 0 | C10: 0 | D10: 0 | E10: 0 | F10: 2 | G10: 37 | H10: 0 | I10: 0.1 | J10: 0 | K10: 0.8 | L10: Feb | M10: 2 | N10: 2 | O10: 2 | P10: 3 | Q10: Returning_Visitor | R10: =FALSE() -> FALSE | S10: =FALSE() -> FALSE | T10: 0 | U10: 0 | V10: 1
A11: 10 | B11: 0 | C11: 0 | D11: 0 | E11: 0 | F11: 3 | G11: 738 | H11: 0 | I11: 0.022222222 | J11: 0 | K11: 0.4 | L11: Feb | M11: 2 | N11: 4 | O11: 1 | P11: 2 | Q11: Returning_Visitor | R11: =FALSE() -> FALSE | S11: =FALSE() -> FALSE | T11: 0 | U11: 0 | V11: 1
A12: 11 | B12: 0 | C12: 0 | D12: 0 | E12: 0 | F12: 3 | G12: 395 | H12: 0 | I12: 0.066666667 | J12: 0 | K12: 0 | L12: Feb | M12: 1 | N12: 1 | O12: 3 | P12: 3 | Q12: Returning_Visitor | R12: =FALSE() -> FALSE | S12: =FALSE() -> FALSE | T12: 0 | U12: 0 | V12: 1
A13: 12 | B13: 0 | C13: 0 | D13: 0 | E13: 0 | F13: 16 | G13: 407.75 | H13: 0.01875 | I13: 0.025833333 | J13: 0 | K13: 0.4 | L13: Feb | M13: 1 | N13: 1 | O13: 4 | P13: 3 | Q13: Returning_Visitor | R13: =FALSE() -> FALSE | S13: =FALSE() -> FALSE | T13: 0 | U13: 0 | V13: 1
A14: 13 | B14: 0 | C14: 0 | D14: 0 | E14: 0 | F14: 7 | G14: 280.5 | H14: 0 | I14: 0.028571429 | J14: 0 | K14: 0 | L14: Feb | M14: 1 | N14: 1 | O14: 1 | P14: 3 | Q14: Returning_Visitor | R14: =FALSE() -> FALSE | S14: =FALSE() -> FALSE | T14: 0 | U14: 0 | V14: 1
A15: 14 | B15: 0 | C15: 0 | D15: 0 | E15: 0 | F15: 6 | G15: 98 | H15: 0 | I15: 0.066666667 | J15: 0 | K15: 0 | L15: Feb | M15: 2 | N15: 5 | O15: 1 | P15: 3 | Q15: Returning_Visitor | R15: =FALSE() -> FALSE | S15: =FALSE() -> FALSE | T15: 0 | U15: 0 | V15: 1
A16: 15 | B16: 0 | C16: 0 | D16: 0 | E16: 0 | F16: 2 | G16: 68 | H16: 0 | I16: 0.1 | J16: 0 | K16: 0 | L16: Feb | M16: 3 | N16: 2 | O16: 3 | P16: 3 | Q16: Returning_Visitor | R16: =FALSE() -> FALSE | S16: =FALSE() -> FALSE | T16: 0 | U16: 0 | V16: 1
A17: 16 | B17: 2 | C17: 53 | D17: 0 | E17: 0 | F17: 23 | G17: 1668.2851 | H17: 0.008333333 | I17: 0.016312636 | J17: 0 | K17: 0 | L17: Feb | M17: 1 | N17: 1 | O17: 9 | P17: 3 | Q17: Returning_Visitor | R17: =FALSE() -> FALSE | S17: =FALSE() -> FALSE | T17: 0 | U17: 0 | V17: 1
A18: 17 | B18: 0 | C18: 0 | D18: 0 | E18: 0 | F18: 1 | G18: 0 | H18: 0.2 | I18: 0.2 | J18: 0 | K18: 0 | L18: Feb | M18: 1 | N18: 1 | O18: 4 | P18: 3 | Q18: Returning_Visitor | R18: =FALSE() -> FALSE | S18: =FALSE() -> FALSE | T18: 0 | U18: 0 | V18: 1
A19: 18 | B19: 0 | C19: 0 | D19: 0 | E19: 0 | F19: 13 | G19: 334.96667 | H19: 0 | I19: 0.007692308 | J19: 0 | K19: 0 | L19: Feb | M19: 1 | N19: 1 | O19: 1 | P19: 4 | Q19: Returning_Visitor | R19: =TRUE() -> TRUE | S19: =FALSE() -> FALSE | T19: 0 | U19: 1 | V19: 1
A20: 19 | B20: 0 | C20: 0 | D20: 0 | E20: 0 | F20: 2 | G20: 32 | H20: 0 | I20: 0.1 | J20: 0 | K20: 0 | L20: Feb | M20: 2 | N20: 2 | O20: 1 | P20: 3 | Q20: Returning_Visitor | R20: =FALSE() -> FALSE | S20: =FALSE() -> FALSE | T20: 0 | U20: 0 | V20: 1
A21: 20 | B21: 0 | C21: 0 | D21: 0 | E21: 0 | F21: 20 | G21: 2981.1667 | H21: 0 | I21: 0.01 | J21: 0 | K21: 0 | L21: Feb | M21: 2 | N21: 4 | O21: 4 | P21: 4 | Q21: Returning_Visitor | R21: =FALSE() -> FALSE | S21: =FALSE() -> FALSE | T21: 0 | U21: 0 | V21: 1
A22: 21 | B22: 0 | C22: 0 | D22: 0 | E22: 0 | F22: 8 | G22: 136.16667 | H22: 0 | I22: 0.008333333 | J22: 0 | K22: 1 | L22: Feb | M22: 2 | N22: 2 | O22: 5 | P22: 1 | Q22: Returning_Visitor | R22: =TRUE() -> TRUE | S22: =FALSE() -> FALSE | T22: 0 | U22: 1 | V22: 1
A23: 22 | B23: 0 | C23: 0 | D23: 0 | E23: 0 | F23: 2 | G23: 0 | H23: 0.2 | I23: 0.2 | J23: 0 | K23: 0 | L23: Feb | M23: 3 | N23: 3 | O23: 1 | P23: 3 | Q23: Returning_Visitor | R23: =FALSE() -> FALSE | S23: =FALSE() -> FALSE | T23: 0 | U23: 0 | V23: 1
A24: 23 | B24: 0 | C24: 0 | D24: 0 | E24: 0 | F24: 3 | G24: 105 | H24: 0 | I24: 0.033333333 | J24: 0 | K24: 0 | L24: Feb | M24: 3 | N24: 2 | O24: 1 | P24: 5 | Q24: Returning_Visitor | R24: =FALSE() -> FALSE | S24: =FALSE() -> FALSE | T24: 0 | U24: 0 | V24: 1
A25: 24 | B25: 0 | C25: 0 | D25: 0 | E25: 0 | F25: 2 | G25: 15 | H25: 0 | I25: 0.1 | J25: 0 | K25: 0.8 | L25: Feb | M25: 2 | N25: 4 | O25: 1 | P25: 3 | Q25: Returning_Visitor | R25: =FALSE() -> FALSE | S25: =FALSE() -> FALSE | T25: 0 | U25: 0 | V25: 1
A26: 25 | B26: 0 | C26: 0 | D26: 0 | E26: 0 | F26: 1 | G26: 0 | H26: 0.2 | I26: 0.2 | J26: 0 | K26: 0 | L26: Feb | M26: 2 | N26: 2 | O26: 4 | P26: 1 | Q26: Returning_Visitor | R26: =TRUE() -> TRUE | S26: =FALSE() -> FALSE | T26: 0 | U26: 1 | V26: 1
A27: 26 | B27: 0 | C27: 0 | D27: 0 | E27: 0 | F27: 5 | G27: 156 | H27: 0 | I27: 0.04 | J27: 0 | K27: 0 | L27: Feb | M27: 1 | N27: 1 | O27: 9 | P27: 3 | Q27: Returning_Visitor | R27: =FALSE() -> FALSE | S27: =FALSE() -> FALSE | T27: 0 | U27: 0 | V27: 1
A28: 27 | B28: 4 | C28: 64.6 | D28: 0 | E28: 0 | F28: 32 | G28: 1135.4444 | H28: 0.002857143 | I28: 0.00952381 | J28: 0 | K28: 0 | L28: Feb | M28: 2 | N28: 2 | O28: 1 | P28: 3 | Q28: Returning_Visitor | R28: =FALSE() -> FALSE | S28: =FALSE() -> FALSE | T28: 0 | U28: 0 | V28: 1
A29: 28 | B29: 0 | C29: 0 | D29: 0 | E29: 0 | F29: 4 | G29: 76 | H29: 0.05 | I29: 0.1 | J29: 0 | K29: 0 | L29: Feb | M29: 1 | N29: 1 | O29: 1 | P29: 3 | Q29: Returning_Visitor | R29: =FALSE() -> FALSE | S29: =FALSE() -> FALSE | T29: 0 | U29: 0 | V29: 1
A30: 29 | B30: 0 | C30: 0 | D30: 0 | E30: 0 | F30: 4 | G30: 63 | H30: 0 | I30: 0.05 | J30: 0 | K30: 0.2 | L30: Feb | M30: 2 | N30: 6 | O30: 1 | P30: 3 | Q30: Returning_Visitor | R30: =FALSE() -> FALSE | S30: =FALSE() -> FALSE | T30: 0 | U30: 0 | V30: 1
A31: 30 | B31: 1 | C31: 6 | D31: 1 | E31: 0 | F31: 45 | G31: 1582.75 | H31: 0.043478261 | I31: 0.050821256 | J31: 54.179764 | K31: 0.4 | L31: Feb | M31: 3 | N31: 2 | O31: 1 | P31: 1 | Q31: Returning_Visitor | R31: =FALSE() -> FALSE | S31: =FALSE() -> FALSE | T31: 0 | U31: 0 | V31: 1
A32: 31 | B32: 0 | C32: 0 | D32: 0 | E32: 0 | F32: 2 | G32: 35 | H32: 0 | I32: 0.1 | J32: 0 | K32: 0 | L32: Feb | M32: 1 | N32: 1 | O32: 6 | P32: 3 | Q32: Returning_Visitor | R32: =FALSE() -> FALSE | S32: =FALSE() -> FALSE | T32: 0 | U32: 0 | V32: 1
A33: 32 | B33: 0 | C33: 0 | D33: 0 | E33: 0 | F33: 3 | G33: 78 | H33: 0 | I33: 0.066666667 | J33: 0 | K33: 0 | L33: Feb | M33: 1 | N33: 2 | O33: 6 | P33: 6 | Q33: Returning_Visitor | R33: =TRUE() -> TRUE | S33: =FALSE() -> FALSE | T33: 0 | U33: 1 | V33: 1
A34: 33 | B34: 0 | C34: 0 | D34: 0 | E34: 0 | F34: 8 | G34: 209.5 | H34: 0 | I34: 0.025 | J34: 0 | K34: 0 | L34: Feb | M34: 2 | N34: 2 | O34: 1 | P34: 1 | Q34: Returning_Visitor | R34: =FALSE() -> FALSE | S34: =FALSE() -> FALSE | T34: 0 | U34: 0 | V34: 1
A35: 34 | B35: 0 | C35: 0 | D35: 0 | E35: 0 | F35: 10 | G35: 183.66667 | H35: 0.04 | I35: 0.08 | J35: 0 | K35: 0 | L35: Feb | M35: 1 | N35: 1 | O35: 3 | P35: 1 | Q35: Returning_Visitor | R35: =FALSE() -> FALSE | S35: =FALSE() -> FALSE | T35: 0 | U35: 0 | V35: 1
A36: 35 | B36: 0 | C36: 0 | D36: 0 | E36: 0 | F36: 14 | G36: 380.5 | H36: 0.014285714 | I36: 0.028571429 | J36: 0 | K36: 0 | L36: Feb | M36: 2 | N36: 2 | O36: 1 | P36: 1 | Q36: Returning_Visitor | R36: =FALSE() -> FALSE | S36: =FALSE() -> FALSE | T36: 0 | U36: 0 | V36: 1
A37: 36 | B37: 0 | C37: 0 | D37: 0 | E37: 0 | F37: 52 | G37: 2086.2429 | H37: 0.015384615 | I37: 0.020352564 | J37: 0 | K37: 0 | L37: Feb | M37: 2 | N37: 2 | O37: 7 | P37: 1 | Q37: Returning_Visitor | R37: =FALSE() -> FALSE | S37: =FALSE() -> FALSE | T37: 0 | U37: 0 | V37: 1
A38: 37 | B38: 0 | C38: 0 | D38: 0 | E38: 0 | F38: 8 | G38: 388 | H38: 0.025 | I38: 0.05625 | J38: 0 | K38: 0 | L38: Feb | M38: 3 | N38: 2 | O38: 1 | P38: 4 | Q38: Returning_Visitor | R38: =TRUE() -> TRUE | S38: =FALSE() -> FALSE | T38: 0 | U38: 1 | V38: 1
A39: 38 | B39: 2 | C39: 18 | D39: 0 | E39: 0 | F39: 5 | G39: 298 | H39: 0 | I39: 0.028571429 | J39: 0 | K39: 0.8 | L39: Feb | M39: 2 | N39: 2 | O39: 8 | P39: 4 | Q39: Returning_Visitor | R39: =FALSE() -> FALSE | S39: =FALSE() -> FALSE | T39: 0 | U39: 0 | V39: 1
A40: 39 | B40: 0 | C40: 0 | D40: 0 | E40: 0 | F40: 7 | G40: 63 | H40: 0.028571429 | I40: 0.071428571 | J40: 0 | K40: 0.6 | L40: Feb | M40: 2 | N40: 2 | O40: 1 | P40: 3 | Q40: Returning_Visitor | R40: =FALSE() -> FALSE | S40: =FALSE() -> FALSE | T40: 0 | U40: 0 | V40: 1
...

Sheet TASK 1 - EDA
A1: TASK 1 – EXPLORATORY DATA ANALYSIS | N1: POPULATION (QUẦN THỂ NGHIÊN CỨU)
N2: Quần thể (Population) | P2: Toàn bộ các phiên truy cập mua sắm trực tuyến (online shopping sessions) trên nền tảng thương mại điện tử được khảo sát
N3: Đơn vị quan sát | P3: 1 phiên truy cập (session) của 1 khách hàng
A4: Structure, data quality, descriptive statistics, outliers and visualizations | N4: Mẫu (Sample) | P4: n = 12,330 phiên, thu thập trong 1 năm (bộ dữ liệu UCI ML Repository, ID 468)
N5: Mục tiêu Task 1 | P5: Mô tả đặc điểm phân phối của mẫu để suy diễn đặc điểm của quần thể
A6: 1A. Structure and data quality
A7: Measure | B7: Result | C7: Interpretation
A8: Rows | B8: 12330 | C8: One row per online session
A9: Original variables | B9: 18 | C9: 10 numerical and 8 categorical/Boolean attributes
A10: Missing cells | B10: 0 | C10: No missing values
A11: Duplicate rows | B11: 125 | C11: Exact duplicate feature vectors are flagged, not removed automatically
A12: Purchase sessions | B12: 1908 | C12: Revenue = TRUE
A13: Non-purchase sessions | B13: 10422 | C13: Revenue = FALSE
A14: Minimum group size | B14: 1908 | C14: Exceeds required 500 observations
A17: 1B–1C. Descriptive statistics for all 10 numerical variables
A18: Group | B18: Variable | C18: n | D18: Mean | E18: Median | F18: SD | G18: Min | H18: Q1 | I18: Q3 | J18: Max | K18: Skewness | L18: IQR outliers
A19: Purchase | B19: Administrative | C19: 1908 | D19: 3.3936059 | E19: 2 | F19: 3.7305273 | G19: 0 | H19: 0 | I19: 5 | J19: 26 | K19: 1.4549978 | L19: 58
A20: Purchase | B20: Administrative_Duration | C20: 1908 | D20: 119.48324 | E20: 52.366667 | F20: 201.11473 | G20: 0 | H20: 0 | I20: 151.08333 | J20: 2086.75 | K20: 3.9852424 | L20: 143
A21: Purchase | B21: Informational | C21: 1908 | D21: 0.78616352 | E21: 0 | F21: 1.5211763 | G21: 0 | H21: 0 | I21: 1 | J21: 12 | K21: 2.6985859 | L21: 223
A22: Purchase | B22: Informational_Duration | C22: 1908 | D22: 57.611427 | E22: 0 | F22: 171.61913 | G22: 0 | H22: 0 | I22: 19 | J22: 1767.6667 | K22: 4.982568 | L22: 367
A23: Purchase | B23: ProductRelated | C23: 1908 | D23: 48.210168 | E23: 29 | F23: 58.267365 | G23: 0 | H23: 15 | I23: 57 | J23: 534 | K23: 3.2594306 | L23: 166
A24: Purchase | B24: ProductRelated_Duration | C24: 1908 | D24: 1876.2096 | E24: 1109.9062 | F24: 2312.2144 | G24: 0 | H24: 541.90625 | I24: 2266.0113 | J24: 27009.859 | K24: 3.3376108 | L24: 166
A25: Purchase | B25: BounceRates | C25: 1908 | D25: 0.0051171526 | E25: 0 | F25: 0.012184512 | G25: 0 | H25: 0 | I25: 0.006451613 | J25: 0.2 | K25: 8.2771729 | L25: 156
A26: Purchase | B26: ExitRates | C26: 1908 | D26: 0.019555168 | E26: 0.016 | F26: 0.016463316 | G26: 0 | H26: 0.0095214825 | I26: 0.025 | J26: 0.2 | K26: 3.4776836 | L26: 95
A27: Purchase | B27: PageValues | C27: 1908 | D27: 27.264518 | E27: 16.758134 | F27: 35.191954 | G27: 0 | H27: 3.6411444 | I27: 38.897742 | J27: 361.76374 | K27: 3.2516528 | L27: 89
A28: Purchase | B28: SpecialDay | C28: 1908 | D28: 0.023165618 | E28: 0 | F28: 0.12352131 | G28: 0 | H28: 0 | I28: 0 | J28: 1 | K28: 5.7919019 | L28: 77
A29: No purchase | B29: Administrative | C29: 10422 | D29: 2.1177317 | E29: 0 | F29: 3.2024806 | G29: 0 | H29: 0 | I29: 3 | J29: 27 | K29: 2.095139 | L29: 793
A30: No purchase | B30: Administrative_Duration | C30: 10422 | D30: 73.740111 | E30: 0 | F30: 171.01797 | G30: 0 | H30: 0 | I30: 83 | J30: 3398.75 | K30: 6.1038852 | L30: 1042
... A38: No purchase | B38: SpecialDay | C38: 10422 | D38: 0.068432163 | E38: 0 | F38: 0.20905382 | G38: 0 | H38: 0 | I38: 0 | J38: 1 | K38: 3.0833801 | L38: 1174
A40: 1D–1E. Visualizations and distribution interpretation
A50: 1D–1E. Visualizations and distribution interpretation
A60: 1D–1E. Visualizations and distribution interpretation
A70: 1D–1E. Visualizations and distribution interpretation

Sheet TASK 2 - ONE POP
A1: TASK 2 – INFERENCE FOR ONE POPULATION | N1: POPULATION (QUẦN THỂ NGHIÊN CỨU)
N2: Quần thể (Population) | P2: Toàn bộ các phiên mua sắm trực tuyến trên nền tảng (không phân biệt có mua hàng hay không)
N3: Tham số μ | P3: Trung bình thời lượng xem trang sản phẩm (ProductRelated_Duration) của toàn bộ quần thể
A4: All 12,330 sessions | two-sided α = 0.05 | 95% confidence intervals | N4: Tham số p | P4: Tỷ lệ phiên dẫn đến mua hàng (Revenue = TRUE) trong toàn bộ quần thể
N5: Mẫu (Sample) | P5: n = 12,330 phiên, được xem là mẫu ngẫu nhiên đại diện cho quần thể
A6: 2A. Hypothesis test and confidence interval for a population mean
A7: Variable: ProductRelated_Duration (seconds). H₀: μ = 1,200; H₁: μ ≠ 1,200. The benchmark represents 20 minutes of product-page engagement. Since population σ is unknown, use a one-sample t procedure.
A11: Measure | B11: Value | C11: Mathematical / Excel calculation
A12: n | B12: 12330 | C12: n = COUNT(x)
A13: Sample mean x̄ | B13: 1194.7462 | C13: x̄ = Σxᵢ/n = AVERAGE(range)
A14: Sample SD s | B14: 1913.6693 | C14: s = √[Σ(xᵢ−x̄)²/(n−1)] = STDEV.S(range)
A15: Hypothesized mean μ₀ | B15: 1200 | C15: μ₀ = 1,200
A16: Test statistic t | B16: -0.30485024 | C16: t = (x̄−μ₀)/(s/√n)
A17: Degrees of freedom | B17: 12329 | C17: df = n−1
A18: Two-sided p-value | B18: 0.76048536 | C18: p = 2P(Tdf ≥ |t|)
A19: 95% CI lower | B19: 1160.9649 | C19: x̄ − t₀.₀₂₅,df·s/√n
A20: 95% CI upper | B20: 1228.5275 | C20: x̄ + t₀.₀₂₅,df·s/√n
A21: Decision | B21: Fail to reject H₀ | C21: There is insufficient evidence that the mean differs from 1,200 seconds.
A24: 2B. Hypothesis test and confidence interval for a population proportion
A25: Outcome: Revenue = TRUE. H₀: p = 0.15; H₁: p ≠ 0.15. The benchmark is a 15% session conversion rate. Normal-approximation conditions np₀ and n(1−p₀) are both far above 10.
A29: Measure | B29: Value | C29: Mathematical / Excel calculation
A30: Sessions n | B30: 12330 | C30: n = COUNT
A31: Purchases x | B31: 1908 | C31: x = SUM(Revenue_int)
A32: Sample proportion p̂ | B32: 0.15474453 | C32: p̂ = x/n
A33: Hypothesized p₀ | B33: 0.15 | C33: p₀ = 0.15
A34: z statistic | B34: 1.4754321 | C34: z = (p̂−p₀)/√[p₀(1−p₀)/n]
A35: Two-sided p-value | B35: 0.1400964 | C35: p = 2[1−Φ(|z|)]
A36: 95% CI lower | B36: 0.14836089 | C36: p̂ − z₀.₀₂₅√[p̂(1−p̂)/n]
A37: 95% CI upper | B37: 0.16112816 | C37: p̂ + z₀.₀₂₅√[p̂(1−p̂)/n]
A38: Decision | B38: Fail to reject H₀ | C38: There is insufficient evidence that conversion differs from 15%.
A41: Interpretation
A42: The estimated average product-page duration is 1,194.7 seconds (95% CI 1,161.0–1,228.5); p=0.7605 against 1,200 seconds. The estimated conversion rate is 15.47% (95% CI 14.84%–16.11%); p=0.1401 against 15%. Neither benchmark difference is statistically significant at α=.05.

Sheet TASK3- MEAN
K1: POPULATION 1 — PURCHASE (Revenue = TRUE), n = 1908 | O1: POPULATION 2 — NO PURCHASE (Revenue = FALSE), n = 10422
A2: TASK 3A — Is there a difference in mean ProductRelated_Duration between Purchase and No-purchase sessions? (α = 0.05) | K2: Session_ID | L2: ProductRelated_Duration | M2: Returning_Visitor (0/1) | O2: Session_ID | P2: ProductRelated_Duration | Q2: Returning_Visitor (0/1)
K3: 66 | L3: 798.33333 | M3: 1 | O3: 1 | P3: 0 | Q3: 1
A4: t-Test: Two-Sample Assuming Unequal Variances | E4: Ho: | F4: μ_purchase − μ_no-purchase = 0 | K4: 77 | L4: 2111.3417 | M4: 1 | O4: 2 | P4: 64 | Q4: 1
B5: Purchase | C5: No purchase | E5: H1: | F5: μ_purchase − μ_no-purchase ≠ 0 (two-tailed) | K5: 102 | L5: 607 | M5: 1 | O5: 3 | P5: 0 | Q5: 1
A6: Mean | B6: =AVERAGE($L$3:$L$1910) -> 1876.2096 | C6: =AVERAGE($P$3:$P$10424) -> 1069.9878 | E6: t Critical = | F6: =B15 -> 1.960974 | K6: 189 | L6: 1868.8197 | M6: 1 | O6: 4 | P6: 2.6666667 | Q6: 1
A7: Variance | B7: =VAR($L$3:$L$1910) -> 5346335.4 | C7: =VAR($P$3:$P$10424) -> 3253686.3 | E7: t Stat (t0) = | F7: =B11 -> 14.446989 | K7: 197 | L7: 2563.7833 | M7: 0 | O7: 5 | P7: 627.5 | Q7: 1
A8: Observations | B8: =COUNT($L$3:$L$1910) -> 1908 | C8: =COUNT($P$3:$P$10424) -> 10422 | E8: Decision | F8: =IF(ABS(B11)>B15,"Reject Ho","Fail to reject Ho") -> Reject Ho | K8: 199 | L8: 840.23333 | M8: 0 | O8: 6 | P8: 154.21667 | Q8: 1
A9: Hypothesized Mean Difference | B9: 0 | E9: Conclusion: | F9: =IF(ABS(B11)>B15,"There IS evidence of a difference in mean ProductRelated_Duration between Purchase and No-purchase sessions.","There is NOT enough evidence of a difference.") -> There IS evidence of a difference in mean ProductRelated_Duration between Purchase and No-purchase sessions. | K9: 200 | L9: 1970.8448 | M9: 0 | O9: 7 | P9: 0 | Q9: 1
A10: df | B10: =(B7/B8+C7/C8)^2/(((B7/B8)^2)/(B8-1)+((C7/C8)^2)/(C8-1)) -> 2350.2735 | K10: 201 | L10: 2867 | M10: 1 | O10: 8 | P10: 0 | Q10: 1
A11: t Stat | B11: =(B6-C6)/SQRT(B7/B8+C7/C8) -> 14.446989 | K11: 207 | L11: 1331.75 | M11: 0 | O11: 9 | P11: 37 | Q11: 1
A12: P(T<=t) one-tail | B12: =_xlfn.T.DIST.RT(ABS(B11),B10) -> 1.0874238e-45 | K12: 221 | L12: 643 | M12: 1 | O12: 10 | P12: 738 | Q12: 1
A13: t Critical one-tail | B13: =_xlfn.T.INV(0.95,B10) -> 1.6455023 | K13: 229 | L13: 2337 | M13: 1 | O13: 11 | P13: 395 | Q13: 1
A14: P(T<=t) two-tail | B14: =_xlfn.T.DIST.2T(ABS(B11),B10) -> 2.1748476e-45 | K14: 249 | L14: 908.01346 | M14: 1 | O14: 12 | P14: 407.75 | Q14: 1
A15: t Critical two-tail | B15: =_xlfn.T.INV.2T(0.05,B10) -> 1.960974 | K15: 263 | L15: 1916.7619 | M15: 1 | O15: 13 | P15: 280.5 | Q15: 1
K16: 266 | L16: 5220.0833 | M16: 1 | O16: 14 | P16: 98 | Q16: 1
K17: 277 | L17: 197.2 | M17: 1 | O17: 15 | P17: 68 | Q17: 1
K18: 282 | L18: 300.07143 | M18: 1 | O18: 16 | P18: 1668.2851 | Q18: 1
A19: TASK 3B — Is there a difference in the proportion of Returning Visitors between Purchase and No-purchase sessions? (α = 0.05) | K19: 295 | L19: 603.66667 | M19: 1 | O19: 17 | P19: 0 | Q19: 1
K20: 296 | L20: 328.91667 | M20: 1 | O20: 18 | P20: 334.96667 | Q20: 1
A21: z-Test: Two-Sample for Proportions | E21: Ho: | F21: p_purchase − p_no-purchase = 0 | K21: 321 | L21: 1483.6 | M21: 1 | O21: 19 | P21: 32 | Q21: 1
B22: Purchase | C22: No purchase | E22: H1: | F22: p_purchase − p_no-purchase ≠ 0 (two-tailed) | K22: 356 | L22: 1992.8333 | M22: 1 | O22: 20 | P22: 2981.1667 | Q22: 1
A23: Sample Proportion (p̂) | B23: =AVERAGE($M$3:$M$1910) -> 0.77044025 | C23: =AVERAGE($Q$3:$Q$10424) -> 0.87132988 | E23: z Critical = | F23: =B32 -> 1.959964 | K23: 366 | L23: 341 | M23: 0 | O23: 21 | P23: 136.16667 | Q23: 1
A24: Observations (n) | B24: =COUNT($M$3:$M$1910) -> 1908 | C24: =COUNT($Q$3:$Q$10424) -> 10422 | E24: z Stat (z0) = | F24: =B28 -> -11.530762 | K24: 380 | L24: 1034.975 | M24: 1 | O24: 22 | P24: 0 | Q24: 1
A25: Successes (x) | B25: =SUM($M$3:$M$1910) -> 1470 | C25: =SUM($Q$3:$Q$10424) -> 9081 | E25: Decision | F25: =IF(ABS(B28)>B32,"Reject Ho","Fail to reject Ho") -> Reject Ho | K25: 391 | L25: 1532.2 | M25: 1 | O25: 23 | P25: 105 | Q25: 1
A26: Hypothesized Proportion Difference | B26: 0 | E26: Conclusion: | F26: =IF(ABS(B28)>B32,"There IS evidence of a difference in Returning-Visitor proportion between Purchase and No-purchase sessions.","There is NOT enough evidence of a difference.") -> There IS evidence of a difference in Returning-Visitor proportion between Purchase and No-purchase sessions. | K26: 400 | L26: 1204.6004 | M26: 1 | O26: 24 | P26: 15 | Q26: 1
A27: Pooled Proportion (p̄) | B27: =(B25+C25)/(B24+C24) -> 0.85571776 | K27: 401 | L27: 1743.3667 | M27: 1 | O27: 25 | P27: 0 | Q27: 1
A28: z Stat | B28: =(B23-C23)/SQRT(B27*(1-B27)*(1/B24+1/C24)) -> -11.530762 | K28: 409 | L28: 1569.625 | M28: 1 | O28: 26 | P28: 156 | Q28: 1
A29: P(Z<=z) one-tail | B29: =1-_xlfn.NORM.S.DIST(ABS(B28),TRUE()) -> 0 | K29: 417 | L29: 245 | M29: 1 | O29: 27 | P29: 1135.4444 | Q29: 1
A30: z Critical one-tail | B30: =_xlfn.NORM.S.INV(0.95) -> 1.6448536 | K30: 425 | L30: 5042.4581 | M30: 1 | O30: 28 | P30: 76 | Q30: 1
A31: P(Z<=z) two-tail | B31: =2*(1-_xlfn.NORM.S.DIST(ABS(B28),TRUE())) -> 0 | K31: 458 | L31: 766.5 | M31: 0 | O31: 29 | P31: 63 | Q31: 1
A32: z Critical two-tail | B32: =_xlfn.NORM.S.INV(0.975) -> 1.959964 | K32: 504 | L32: 2868.1333 | M32: 1 | O32: 30 | P32: 1582.75 | Q32: 1
K33: 511 | L33: 11301.204 | M33: 1 | O33: 31 | P33: 35 | Q33: 1
K34: 588 | L34: 2122.6561 | M34: 1 | O34: 32 | P34: 78 | Q34: 1
K35: 602 | L35: 2585.6184 | M35: 1 | O35: 33 | P35: 209.5 | Q35: 1
K36: 604 | L36: 808.5 | M36: 1 | O36: 34 | P36: 183.66667 | Q36: 1
K37: 610 | L37: 179 | M37: 0 | O37: 35 | P37: 380.5 | Q37: 1
K38: 611 | L38: 2720.6714 | M38: 1 | O38: 36 | P38: 2086.2429 | Q38: 1
K39: 613 | L39: 2309.7325 | M39: 1 | O39: 37 | P39: 388 | Q39: 1
K40: 615 | L40: 694 | M40: 1 | O40: 38 | P40: 298 | Q40: 1
...

Sheet TASK 4 - REGRESSION
A1: TASK 4 – SIMPLE LINEAR REGRESSION
A4: X = ProductRelated pages | Y = ProductRelated_Duration in seconds
A6: 4A–4B. Variable selection and scatter plot
A7: The number of product pages viewed should naturally relate to total product-page time and provides an interpretable platform-engagement model. The scatter plot shows a strong, positive, approximately linear relationship with increasing spread at high page counts.
A37: 4C–4D–4F. Correlation, fitted model and slope test
A38: Measure | B38: Value | C38: Mathematical / Excel calculation | E38: Estimated equation: Ŷ = 19.301 + 37.044X r = 0.861: strong positive sample correlation. R² = 74.1%, so page count explains approximately 74.1% of the observed variation in product-page duration under this linear model.
A39: Observations n | B39: 12330 | C39: n
A40: Correlation r | B40: 0.86092684 | C40: r = Σ[(xᵢ−x̄)(yᵢ−ȳ)] / √[Σ(xᵢ−x̄)²Σ(yᵢ−ȳ)²]
A41: R squared | B41: 0.74119502 | C41: R²=r²=SSR/SST
A42: Intercept b₀ | B42: 19.300917 | C42: b₀=ȳ−b₁x̄
A43: Slope b₁ | B43: 37.043521 | C43: b₁=Σ[(xᵢ−x̄)(yᵢ−ȳ)]/Σ(xᵢ−x̄)²
A44: Residual standard error | B44: 973.57815 | C44: sₑ=√[SSE/(n−2)]
A45: Slope standard error | B45: 0.19714511 | C45: SE(b₁) | E45: Coefficient interpretation: b₀ = 19.301: at X = 0, the fitted value is 19.301 seconds. This has limited practical meaning because no product-page view should imply near-zero product-page duration. b₁ = 37.044: each additional product page is associated with an average increase of about 37.04 seconds in total product-page duration.
A46: Slope t statistic | B46: 187.89977 | C46: t=b₁/SE(b₁)
A47: Slope p-value | B47: < 0.001 | C47: Report as p < 0.001; the value is not literally zero.
A48: Slope 95% lower | B48: 36.657086 | C48: b₁−t*SE(b₁)
A49: Slope 95% upper | B49: 37.429956 | C49: b₁+t*SE(b₁)
A50: Decision | B50: Reject H₀ | C50: The slope is statistically different from zero (p<.001).
A53: 4E. Predictions for selected X values
A54: Pages viewed X | B54: Predicted duration Ŷ (seconds) | C54: Formula
A55: 10 | B55: 389.73613 | C55: Ŷ=b₀+b₁X
A56: 25 | B56: 945.38894 | C56: Ŷ=b₀+b₁X
A57: 50 | B57: 1871.477 | C57: Ŷ=b₀+b₁X
A58: 100 | B58: 3723.653 | C58: Ŷ=b₀+b₁X
A59: 200 | B59: 7428.0051 | C59: Ŷ=b₀+b₁X
A61: Regression interpretation and caution
A62: Each additional product page is associated with about 37.04 additional seconds of product-page time on average. The slope is highly statistically significant, and the association is practically strong. However, residual spread grows for long sessions, and the model should not be used beyond the observed page-count range. This regression measures engagement mechanics, not a causal effect on purchase completion.
A70: 4F. Detailed hypothesis test for the slope coefficient
A71: Hypotheses and significance level: H₀: β₁ = 0 (no population linear relationship) H₁: β₁ ≠ 0 (a population linear relationship exists) α = 0.05; two-sided test; df = n − 2 = 12,328
A76: Quantity | B76: Value | C76: Mathematical calculation | D76: Interpretation
A77: Observations n | B77: 12330 | C77: n | D77: All sessions
A78: Sxx | B78: 24387630 | C78: Sxx = Σ(xᵢ − x̄)² | D78: Variation in X used to estimate the slope
A79: SSE | B79: 1.1685149e+10 | C79: SSE = Σ(yᵢ − ŷᵢ)² | D79: Unexplained sum of squares
A80: Degrees of freedom | B80: 12328 | C80: df = n − 2 | D80: Regression residual degrees of freedom
A81: MSE | B81: 947854.41 | C81: MSE = SSE/(n − 2) | D81: Estimated residual variance
A82: Residual standard error sₑ | B82: 973.57815 | C82: sₑ = √MSE | D82: Typical residual scale, in seconds
A83: Slope standard error | B83: 0.19714511 | C83: SE(b₁) = sₑ/√Sxx | D83: Sampling uncertainty of b₁
A84: Estimated slope b₁ | B84: 37.043521 | C84: b₁ = Sxy/Sxx | D84: Seconds associated with one additional page
A85: Test statistic t₀ | B85: 187.89977 | C85: t₀ = (b₁ − 0)/SE(b₁) | D85: Observed standardized distance from H₀
A86: Two-sided critical value | B86: 1.9601564 | C86: ±t₀.₀₂₅,₁₂₃₂₈ | D86: Reject H₀ when |t₀| > 1.9602
...

Sheet MATHEMATICAL FORMULAS
A1: MATHEMATICAL FORMULAS USED
A4: Notation, assumptions and Excel-equivalent functions
A6: Core descriptive and inferential formulas
A7: Quantity | B7: Mathematical formula | C7: Excel equivalent | D7: Use / condition
A8: Sample mean | B8: x̄ = (1/n)Σᵢ₌₁ⁿxᵢ | C8: AVERAGE(range) | D8: Center of a quantitative sample
A9: Sample variance | B9: s² = Σ(xᵢ−x̄)²/(n−1) | C9: VAR.S(range) | D9: Squared dispersion
A10: Mean confidence interval | B10: x̄ ± tα/2,n−1·s/√n | C10: CONFIDENCE.T(alpha,STDEV.S(range),COUNT(range)) | D10: Unknown population SD
A11: One-mean t test | B11: t=(x̄−μ₀)/(s/√n) | C11: T.DIST.2T(ABS(t),n-1) | D11: Two-sided test
A12: Sample proportion | B12: p̂=x/n | C12: SUM(binary)/COUNT(binary) | D12: Binary outcome
A13: Proportion confidence interval | B13: p̂ ± zα/2√[p̂(1−p̂)/n] | C13: NORM.S.INV(1-alpha/2) | D13: Large-sample Wald CI
A14: One-proportion z test | B14: z=(p̂−p₀)/√[p₀(1−p₀)/n] | C14: 2*(1-NORM.S.DIST(ABS(z),TRUE)) | D14: Requires np₀ and n(1−p₀) sufficiently large
A15: Welch mean difference | B15: (x̄₁−x̄₂) ± t*√(s₁²/n₁+s₂²/n₂) | C15: T.TEST(range1,range2,2,3) | D15: Independent samples, unequal variances
A16: Two-proportion z | B16: z=(p̂₁−p̂₂)/√[p̂pool(1−p̂pool)(1/n₁+1/n₂)] | C16: NORM.S.DIST | D16: Pooled SE under H₀
A17: Correlation | B17: r=Σ[(xᵢ−x̄)(yᵢ−ȳ)]/√[Σ(xᵢ−x̄)²Σ(yᵢ−ȳ)²] | C17: CORREL(x_range,y_range) | D17: Direction and strength of linear association
A18: Regression slope | B18: b₁=Σ[(xᵢ−x̄)(yᵢ−ȳ)]/Σ(xᵢ−x̄)² | C18: SLOPE(y_range,x_range) | D18: Expected change in Y per one-unit X
... A22: Coefficient of determination | B22: R²=SSR/SST=1−SSE/SST | C22: RSQ(y_range,x_range) | D22: Explained sample variation
A24: Symbols
A25: Symbol | B25: Meaning
A26: xᵢ, yᵢ | B26: Observed values
A27: x̄, ȳ | B27: Sample means
A28: μ, p | B28: Population mean and proportion
A29: s, s² | B29: Sample standard deviation and variance
A30: n | B30: Sample size
A31: α | B31: Significance level, set to 0.05
A32: H₀, H₁ | B32: Null and alternative hypotheses
A33: SE | B33: Standard error
A34: β₀, β₁ | B34: Population regression intercept and slope
A35: b₀, b₁ | B35: Estimated sample regression coefficients

Sheet TASK 5 - CONCLUSION
A1: TASK 5 – FINAL INTERPRETATION
A4: Key findings, statistical versus practical significance, limitations and implications
A6: Summary of key findings
A7: Analysis | B7: Finding
A8: EDA | B8: 1,908 purchase and 10,422 non-purchase sessions; no missing values; behavioral measures are right-skewed with genuine high-end outliers.
A9: One mean | B9: Mean product-page duration 1,194.7s; 95% CI 1,161.0–1,228.5; not different from 1,200s at α=.05.
A10: One proportion | B10: Conversion 15.47%; 95% CI 14.84%–16.11%; not different from 15% at α=.05.
A11: Two means | B11: Buyers spend 806.2s longer on product pages on average; 95% CI 696.8–915.7; p<.001.
A12: Two proportions | B12: Returning-visitor share differs by -10.1%; 95% CI -12.1%–-8.1%; p<.001.
A13: Regression | B13: r=0.861, R²=74.1%, Ŷ=19.30+37.04X; slope p<.001.
A16: Statistical significance versus practical significance
A17: The duration difference is both statistically significant and practically large: converted sessions spend roughly 13.4 additional minutes on product pages. The returning-visitor composition difference is statistically significant, but it should not be confused with visitor-type conversion probability. The regression effect is practically strong because page count explains a large share of engagement time. In contrast, the overall mean and conversion rate are close enough to their selected benchmarks that the tests are not significant.
A24: Overall conclusions and platform implications
A25: # | B25: Conclusion / implication
A26: 1 | B26: Deeper product exploration is strongly associated with successful conversion.
A27: 2 | B27: High bounce and exit behavior is concentrated more strongly among non-purchase sessions; landing-page relevance and navigation deserve attention.
A28: 3 | B28: Product-page count is an effective descriptive predictor of total engagement time, but not by itself a purchase-causation model.
A29: 4 | B29: Segment-level conversion rates should be examined before targeting returning versus new visitors.
A30: 5 | B30: Operational experiments such as A/B tests are needed to establish causality; this observational dataset supports association and inference only.
A33: Limitations
A34: The data cover one year and anonymized sessions; there is no transaction amount, demographic information or repeat-user identifier available for this workbook. Several variables are highly skewed, the two groups are unbalanced, and multiple session features may be related. Classical tests rely on random/independent sampling and large-sample approximation. UCI designed the dataset so each session belongs to a different user, which supports independence, but conclusions still generalize primarily to the platform and collection process represented by the source data.

Sheet SOURCES
A1: DATA SOURCE AND CITATION
A4: Official UCI repository documentation and reproducibility notes
A6: Primary source
A7: Item | B7: Details
A8: Dataset | B8: Online Shoppers Purchasing Intention Dataset
A9: Creators | B9: C. Sakar and Yomi Kastro
A10: Repository | B10: UCI Machine Learning Repository
A11: Instances / features | B11: 12,330 sessions / 17 predictive features plus Revenue class
A12: Missing values | B12: None
A13: Groups | B13: 10,422 negative; 1,908 positive conversion sessions
A14: License | B14: Creative Commons Attribution 4.0 International (CC BY 4.0)
A15: Dataset page | B15: https://archive.ics.uci.edu/dataset/468/online+shoppers+purchasing+intention+dataset
A16: DOI | B16: https://doi.org/10.24432/C5F88Q
A17: Access date | B17: 18 July 2026
A19: Citation
A20: Sakar, C., & Kastro, Y. (2018). Online Shoppers Purchasing Intention Dataset [Dataset]. UCI Machine Learning Repository. https://doi.org/10.24432/C5F88Q.
A26: Reproducibility
A27: The DATA sheet contains all 12,330 source records plus four explicitly derived binary/index columns: Session_ID, Revenue_int, Weekend_int and Returning_int. No records were deleted. All hypotheses, α=.05 decisions, confidence levels, mathematical formulas and Excel-equivalent functions appear in the analysis and MATHEMATICAL FORMULAS sheets.

Sheet CHART_DATA
A1: Duration bin (seconds) | B1: No purchase | C1: Purchase | D1: Lower | E1: Upper | G1: Statistic | H1: No purchase | I1: Purchase | J1: Month | K1: Conversion rate | M1: Visitor type | N1: No purchase | O1: Purchase | P1: Lower bound | Q1: Upper bound | R1: Duration interval | S1: Frequency
A2: 0–300 | B2: =COUNTIFS(DATA!$T$2:$T$12331,0,DATA!$G$2:$G$12331,">="&D2,DATA!$G$2:$G$12331,"<="&E2)/COUNTIF(DATA!$T$2:$T$12331,0) -> 0.37814239 | C2: =COUNTIFS(DATA!$T$2:$T$12331,1,DATA!$G$2:$G$12331,">="&D2,DATA!$G$2:$G$12331,"<="&E2)/COUNTIF(DATA!$T$2:$T$12331,1) -> 0.11897275 | D2: 0 | E2: 300 | G2: Min | H2: ='TASK 1 - EDA'!G25 -> 0 | I2: ='TASK 1 - EDA'!G20 -> 0 | J2: Feb | K2: =SUMIFS(DATA!$T$2:$T$12331,DATA!$L$2:$L$12331,J2)/COUNTIF(DATA!$L$2:$L$12331,J2) -> 0.016304348 | M2: New_Visitor | N2: =1-O2 -> 0.75088548 | O2: =SUMIFS(DATA!$T$2:$T$12331,DATA!$Q$2:$Q$12331,M2)/COUNTIF(DATA!$Q$2:$Q$12331,M2) -> 0.24911452 | P2: 0 | Q2: 300 | R2: 0–300 | S2: =COUNTIFS(DATA!$G$2:$G$12331,">="&P2,DATA!$G$2:$G$12331,"<"&Q2) -> 4166
A3: 301–600 | B3: =COUNTIFS(DATA!$T$2:$T$12331,0,DATA!$G$2:$G$12331,">"&D3,DATA!$G$2:$G$12331,"<="&E3)/COUNTIF(DATA!$T$2:$T$12331,0) -> 0.16292458 | C3: =COUNTIFS(DATA!$T$2:$T$12331,1,DATA!$G$2:$G$12331,">"&D3,DATA!$G$2:$G$12331,"<="&E3)/COUNTIF(DATA!$T$2:$T$12331,1) -> 0.16142558 | D3: 300 | E3: 600 | G3: Q1 | H3: ='TASK 1 - EDA'!H25 -> 0 | I3: ='TASK 1 - EDA'!H20 -> 0 | J3: Mar | K3: =SUMIFS(DATA!$T$2:$T$12331,DATA!$L$2:$L$12331,J3)/COUNTIF(DATA!$L$2:$L$12331,J3) -> 0.1006817 | M3: Other | N3: =1-O3 -> 0.81176471 | O3: =SUMIFS(DATA!$T$2:$T$12331,DATA!$Q$2:$Q$12331,M3)/COUNTIF(DATA!$Q$2:$Q$12331,M3) -> 0.18823529 | P3: 300 | Q3: 600 | R3: 300–600 | S3: =COUNTIFS(DATA!$G$2:$G$12331,">="&P3,DATA!$G$2:$G$12331,"<"&Q3) -> 2007
A4: 601–1,200 | B4: =COUNTIFS(DATA!$T$2:$T$12331,0,DATA!$G$2:$G$12331,">"&D4,DATA!$G$2:$G$12331,"<="&E4)/COUNTIF(DATA!$T$2:$T$12331,0) -> 0.18173095 | C4: =COUNTIFS(DATA!$T$2:$T$12331,1,DATA!$G$2:$G$12331,">"&D4,DATA!$G$2:$G$12331,"<="&E4)/COUNTIF(DATA!$T$2:$T$12331,1) -> 0.25262055 | D4: 600 | E4: 1200 | G4: Median | H4: ='TASK 1 - EDA'!E25 -> 0 | I4: ='TASK 1 - EDA'!E20 -> 52.366667 | J4: May | K4: =SUMIFS(DATA!$T$2:$T$12331,DATA!$L$2:$L$12331,J4)/COUNTIF(DATA!$L$2:$L$12331,J4) -> 0.10850178 | M4: Returning_Visitor | N4: =1-O4 -> 0.86067671 | O4: =SUMIFS(DATA!$T$2:$T$12331,DATA!$Q$2:$Q$12331,M4)/COUNTIF(DATA!$Q$2:$Q$12331,M4) -> 0.13932329 | P4: 600 | Q4: 900 | R4: 600–900 | S4: =COUNTIFS(DATA!$G$2:$G$12331,">="&P4,DATA!$G$2:$G$12331,"<"&Q4) -> 1422
A5: 1,201–2,400 | B5: =COUNTIFS(DATA!$T$2:$T$12331,0,DATA!$G$2:$G$12331,">"&D5,DATA!$G$2:$G$12331,"<="&E5)/COUNTIF(DATA!$T$2:$T$12331,0) -> 0.16206102 | C5: =COUNTIFS(DATA!$T$2:$T$12331,1,DATA!$G$2:$G$12331,">"&D5,DATA!$G$2:$G$12331,"<="&E5)/COUNTIF(DATA!$T$2:$T$12331,1) -> 0.22955975 | D5: 1200 | E5: 2400 | G5: Q3 | H5: ='TASK 1 - EDA'!I25 -> 0.006451613 | I5: ='TASK 1 - EDA'!I20 -> 151.08333 | J5: June | K5: =SUMIFS(DATA!$T$2:$T$12331,DATA!$L$2:$L$12331,J5)/COUNTIF(DATA!$L$2:$L$12331,J5) -> 0.10069444 | P5: 900 | Q5: 1200 | R5: 900–1,200 | S5: =COUNTIFS(DATA!$G$2:$G$12331,">="&P5,DATA!$G$2:$G$12331,"<"&Q5) -> 955
A6: 2,401–4,800 | B6: =COUNTIFS(DATA!$T$2:$T$12331,0,DATA!$G$2:$G$12331,">"&D6,DATA!$G$2:$G$12331,"<="&E6)/COUNTIF(DATA!$T$2:$T$12331,0) -> 0.083381309 | C6: =COUNTIFS(DATA!$T$2:$T$12331,1,DATA!$G$2:$G$12331,">"&D6,DATA!$G$2:$G$12331,"<="&E6)/COUNTIF(DATA!$T$2:$T$12331,1) -> 0.14779874 | D6: 2400 | E6: 4800 | G6: Max | H6: ='TASK 1 - EDA'!J25 -> 0.2 | I6: ='TASK 1 - EDA'!J20 -> 2086.75 | J6: Jul | K6: =SUMIFS(DATA!$T$2:$T$12331,DATA!$L$2:$L$12331,J6)/COUNTIF(DATA!$L$2:$L$12331,J6) -> 0.15277778 | P6: 1200 | Q6: 1500 | R6: 1,200–1,500 | S6: =COUNTIFS(DATA!$G$2:$G$12331,">="&P6,DATA!$G$2:$G$12331,"<"&Q6) -> 770
A7: 4,801–9,600 | B7: =COUNTIFS(DATA!$T$2:$T$12331,0,DATA!$G$2:$G$12331,">"&D7,DATA!$G$2:$G$12331,"<="&E7)/COUNTIF(DATA!$T$2:$T$12331,0) -> 0.026098637 | C7: =COUNTIFS(DATA!$T$2:$T$12331,1,DATA!$G$2:$G$12331,">"&D7,DATA!$G$2:$G$12331,"<="&E7)/COUNTIF(DATA!$T$2:$T$12331,1) -> 0.071802935 | D7: 4800 | E7: 9600 | J7: Aug | K7: =SUMIFS(DATA!$T$2:$T$12331,DATA!$L$2:$L$12331,J7)/COUNTIF(DATA!$L$2:$L$12331,J7) -> 0.17551963 | P7: 1500 | Q7: 1800 | R7: 1,500–1,800 | S7: =COUNTIFS(DATA!$G$2:$G$12331,">="&P7,DATA!$G$2:$G$12331,"<"&Q7) -> 578
A8: 9,601–19,200 | B8: =COUNTIFS(DATA!$T$2:$T$12331,0,DATA!$G$2:$G$12331,">"&D8,DATA!$G$2:$G$12331,"<="&E8)/COUNTIF(DATA!$T$2:$T$12331,0) -> 0.0048934945 | C8: =COUNTIFS(DATA!$T$2:$T$12331,1,DATA!$G$2:$G$12331,">"&D8,DATA!$G$2:$G$12331,"<="&E8)/COUNTIF(DATA!$T$2:$T$12331,1) -> 0.016771488 | D8: 9600 | E8: 19200 | J8: Sep | K8: =SUMIFS(DATA!$T$2:$T$12331,DATA!$L$2:$L$12331,J8)/COUNTIF(DATA!$L$2:$L$12331,J8) -> 0.19196429 | P8: 1800 | Q8: 2100 | R8: 1,800–2,100 | S8: =COUNTIFS(DATA!$G$2:$G$12331,">="&P8,DATA!$G$2:$G$12331,"<"&Q8) -> 451
A9: 19,201–38,400 | B9: =COUNTIFS(DATA!$T$2:$T$12331,0,DATA!$G$2:$G$12331,">"&D9,DATA!$G$2:$G$12331,"<="&E9)/COUNTIF(DATA!$T$2:$T$12331,0) -> 0.00057570524 | C9: =COUNTIFS(DATA!$T$2:$T$12331,1,DATA!$G$2:$G$12331,">"&D9,DATA!$G$2:$G$12331,"<="&E9)/COUNTIF(DATA!$T$2:$T$12331,1) -> 0.001048218 | D9: 19200 | E9: 38400 | J9: Oct | K9: =SUMIFS(DATA!$T$2:$T$12331,DATA!$L$2:$L$12331,J9)/COUNTIF(DATA!$L$2:$L$12331,J9) -> 0.20947177 | P9: 2100 | Q9: 2400 | R9: 2,100–2,400 | S9: =COUNTIFS(DATA!$G$2:$G$12331,">="&P9,DATA!$G$2:$G$12331,"<"&Q9) -> 328
A10: 38,401–64,000 | B10: =COUNTIFS(DATA!$T$2:$T$12331,0,DATA!$G$2:$G$12331,">"&D10,DATA!$G$2:$G$12331,"<="&E10)/COUNTIF(DATA!$T$2:$T$12331,0) -> 0.00019190175 | C10: =COUNTIFS(DATA!$T$2:$T$12331,1,DATA!$G$2:$G$12331,">"&D10,DATA!$G$2:$G$12331,"<="&E10)/COUNTIF(DATA!$T$2:$T$12331,1) -> 0 | D10: 38400 | E10: 64000 | J10: Nov | K10: =SUMIFS(DATA!$T$2:$T$12331,DATA!$L$2:$L$12331,J10)/COUNTIF(DATA!$L$2:$L$12331,J10) -> 0.25350233 | P10: 2400 | Q10: 2700 | R10: 2,400–2,700 | S10: =COUNTIFS(DATA!$G$2:$G$12331,">="&P10,DATA!$G$2:$G$12331,"<"&Q10) -> 275
J11: Dec | K11: =SUMIFS(DATA!$T$2:$T$12331,DATA!$L$2:$L$12331,J11)/COUNTIF(DATA!$L$2:$L$12331,J11) -> 0.12507238 | P11: 2700 | Q11: 3000 | R11: 2,700–3,000 | S11: =COUNTIFS(DATA!$G$2:$G$12331,">="&P11,DATA!$G$2:$G$12331,"<"&Q11) -> 209
P12: 3000 | Q12: 3300 | R12: 3,000–3,300 | S12: =COUNTIFS(DATA!$G$2:$G$12331,">="&P12,DATA!$G$2:$G$12331,"<"&Q12) -> 167
P13: 3300 | Q13: 3600 | R13: 3,300–3,600 | S13: =COUNTIFS(DATA!$G$2:$G$12331,">="&P13,DATA!$G$2:$G$12331,"<"&Q13) -> 135
P14: 3600 | Q14: 3900 | R14: 3,600–3,900 | S14: =COUNTIFS(DATA!$G$2:$G$12331,">="&P14,DATA!$G$2:$G$12331,"<"&Q14) -> 118
P15: 3900 | Q15: 4200 | R15: 3,900–4,200 | S15: =COUNTIFS(DATA!$G$2:$G$12331,">="&P15,DATA!$G$2:$G$12331,"<"&Q15) -> 99
P16: 4200 | Q16: 4500 | R16: 4,200–4,500 | S16: =COUNTIFS(DATA!$G$2:$G$12331,">="&P16,DATA!$G$2:$G$12331,"<"&Q16) -> 82
P17: 4500 | Q17: 4800 | R17: 4,500–4,800 | S17: =COUNTIFS(DATA!$G$2:$G$12331,">="&P17,DATA!$G$2:$G$12331,"<"&Q17) -> 66
P18: 4800 | Q18: 5100 | R18: 4,800–5,100 | S18: =COUNTIFS(DATA!$G$2:$G$12331,">="&P18,DATA!$G$2:$G$12331,"<"&Q18) -> 61
P19: 5100 | Q19: 5400 | R19: 5,100–5,400 | S19: =COUNTIFS(DATA!$G$2:$G$12331,">="&P19,DATA!$G$2:$G$12331,"<"&Q19) -> 55
P20: 5400 | Q20: 5700 | R20: 5,400–5,700 | S20: =COUNTIFS(DATA!$G$2:$G$12331,">="&P20,DATA!$G$2:$G$12331,"<"&Q20) -> 43
P21: 5700 | Q21: 6000 | R21: 5,700–6,000 | S21: =COUNTIFS(DATA!$G$2:$G$12331,">="&P21,DATA!$G$2:$G$12331,"<="&Q21) -> 35
P22: 6000 | R22: >6,000 | S22: =COUNTIF(DATA!$G$2:$G$12331,">"&P22) -> 308
P23: 0 | Q23: 1034.975
P24: 105 | Q24: 1532.2
P25: 15 | Q25: 1204.6004
P26: 0 | Q26: 1743.3667
P27: 156 | Q27: 1569.625
P28: 1135.4444 | Q28: 245
P29: 76 | Q29: 5042.4581
P30: 63 | Q30: 766.5
P31: 1582.75 | Q31: 2868.1333
P32: 35 | Q32: 11301.204
P33: 78 | Q33: 2122.6561
P34: 209.5 | Q34: 2585.6184
... P1909: 271.125 | Q1909: 2773.5
P1910: 0
P1911: 2564.2782
P1912: 4895.023
P1913: 1449.6833
P1914: 249
...
